[ 2023-10-16 17:31:21,735 ] 12 root - INFO - In App.py
[ 2023-10-16 17:31:21,737 ] 15 root - INFO - Showing Index page
[ 2023-10-16 17:31:21,759 ] 96 werkzeug - INFO - [31m[1mWARNING: This is a development server. Do not use it in a production deployment. Use a production WSGI server instead.[0m
 * Running on all addresses (0.0.0.0)
 * Running on http://127.0.0.1:8080
 * Running on http://192.168.1.37:8080
[ 2023-10-16 17:31:21,759 ] 96 werkzeug - INFO - [33mPress CTRL+C to quit[0m
[ 2023-10-16 17:31:28,119 ] 96 werkzeug - INFO - 127.0.0.1 - - [16/Oct/2023 17:31:28] "GET / HTTP/1.1" 200 -
[ 2023-10-16 17:32:02,989 ] 23 root - INFO - Submit command recieved
[ 2023-10-16 17:32:02,992 ] 40 root - INFO - recieved values [67.0, 'Others', 63.0, 'Others', 'Science', 64.0, 'Sci&Tech', 'No', 60.0, None, 61.87]
[ 2023-10-16 17:32:03,280 ] 16 root - INFO - In Predict py importing models
[ 2023-10-16 17:32:03,452 ] 24 root - INFO - Data Transoformation
[ 2023-10-16 17:32:03,453 ] 26 root - INFO - Predicting Results
[ 2023-10-16 17:32:03,457 ] 39 root - INFO - Error occured in python script name [F:\New folder\CampusPlacementPrediction\prediction.py] line number [27] error message[Found unknown categories [None] in column 5 during transform]
[ 2023-10-16 17:32:03,458 ] 825 app - ERROR - Exception on /submit [POST]
Traceback (most recent call last):
  File "F:\New folder\CampusPlacementPrediction\prediction.py", line 27, in prediction
    data = preprocessor.transform(data)
  File "f:\New folder\CampusPlacementPrediction\venv\lib\site-packages\sklearn\utils\_set_output.py", line 157, in wrapped
    data_to_wrap = f(self, X, *args, **kwargs)
  File "f:\New folder\CampusPlacementPrediction\venv\lib\site-packages\sklearn\compose\_column_transformer.py", line 827, in transform
    Xs = self._fit_transform(
  File "f:\New folder\CampusPlacementPrediction\venv\lib\site-packages\sklearn\compose\_column_transformer.py", line 681, in _fit_transform
    return Parallel(n_jobs=self.n_jobs)(
  File "f:\New folder\CampusPlacementPrediction\venv\lib\site-packages\sklearn\utils\parallel.py", line 65, in __call__
    return super().__call__(iterable_with_config)
  File "f:\New folder\CampusPlacementPrediction\venv\lib\site-packages\joblib\parallel.py", line 1863, in __call__
    return output if self.return_generator else list(output)
  File "f:\New folder\CampusPlacementPrediction\venv\lib\site-packages\joblib\parallel.py", line 1792, in _get_sequential_output
    res = func(*args, **kwargs)
  File "f:\New folder\CampusPlacementPrediction\venv\lib\site-packages\sklearn\utils\parallel.py", line 127, in __call__
    return self.function(*args, **kwargs)
  File "f:\New folder\CampusPlacementPrediction\venv\lib\site-packages\sklearn\pipeline.py", line 940, in _transform_one
    res = transformer.transform(X)
  File "f:\New folder\CampusPlacementPrediction\venv\lib\site-packages\sklearn\pipeline.py", line 696, in transform
    Xt = transform.transform(Xt)
  File "f:\New folder\CampusPlacementPrediction\venv\lib\site-packages\sklearn\utils\_set_output.py", line 157, in wrapped
    data_to_wrap = f(self, X, *args, **kwargs)
  File "f:\New folder\CampusPlacementPrediction\venv\lib\site-packages\sklearn\preprocessing\_encoders.py", line 1027, in transform
    X_int, X_mask = self._transform(
  File "f:\New folder\CampusPlacementPrediction\venv\lib\site-packages\sklearn\preprocessing\_encoders.py", line 200, in _transform
    raise ValueError(msg)
ValueError: Found unknown categories [None] in column 5 during transform

During handling of the above exception, another exception occurred:

Traceback (most recent call last):
  File "f:\New folder\CampusPlacementPrediction\venv\lib\site-packages\flask\app.py", line 1455, in wsgi_app
    response = self.full_dispatch_request()
  File "f:\New folder\CampusPlacementPrediction\venv\lib\site-packages\flask\app.py", line 869, in full_dispatch_request
    rv = self.handle_user_exception(e)
  File "f:\New folder\CampusPlacementPrediction\venv\lib\site-packages\flask\app.py", line 867, in full_dispatch_request
    rv = self.dispatch_request()
  File "f:\New folder\CampusPlacementPrediction\venv\lib\site-packages\flask\app.py", line 852, in dispatch_request
    return self.ensure_sync(self.view_functions[rule.endpoint])(**view_args)
  File "app.py", line 41, in submit
    result = prediction(inputs)
  File "F:\New folder\CampusPlacementPrediction\prediction.py", line 40, in prediction
    raise CustomException(e,sys)
src.exception.CustomException: Error occured in python script name [F:\New folder\CampusPlacementPrediction\prediction.py] line number [27] error message[Found unknown categories [None] in column 5 during transform]
[ 2023-10-16 17:32:03,461 ] 96 werkzeug - INFO - 127.0.0.1 - - [16/Oct/2023 17:32:03] "[35m[1mPOST /submit HTTP/1.1[0m" 500 -
[ 2023-10-16 17:33:30,079 ] 96 werkzeug - INFO - 127.0.0.1 - - [16/Oct/2023 17:33:30] "GET / HTTP/1.1" 200 -
[ 2023-10-16 17:33:58,950 ] 23 root - INFO - Submit command recieved
[ 2023-10-16 17:33:58,954 ] 40 root - INFO - recieved values [67.0, 'Others', 63.0, 'Others', 'Science', 64.0, 'Sci&Tech', 'No', 60.0, None, 61.87]
[ 2023-10-16 17:33:58,954 ] 16 root - INFO - In Predict py importing models
[ 2023-10-16 17:33:58,956 ] 24 root - INFO - Data Transoformation
[ 2023-10-16 17:33:58,959 ] 26 root - INFO - Predicting Results
[ 2023-10-16 17:33:58,965 ] 39 root - INFO - Error occured in python script name [F:\New folder\CampusPlacementPrediction\prediction.py] line number [27] error message[Found unknown categories [None] in column 5 during transform]
[ 2023-10-16 17:33:58,965 ] 825 app - ERROR - Exception on /submit [POST]
Traceback (most recent call last):
  File "F:\New folder\CampusPlacementPrediction\prediction.py", line 27, in prediction
    data = preprocessor.transform(data)
  File "f:\New folder\CampusPlacementPrediction\venv\lib\site-packages\sklearn\utils\_set_output.py", line 157, in wrapped
    data_to_wrap = f(self, X, *args, **kwargs)
  File "f:\New folder\CampusPlacementPrediction\venv\lib\site-packages\sklearn\compose\_column_transformer.py", line 827, in transform
    Xs = self._fit_transform(
  File "f:\New folder\CampusPlacementPrediction\venv\lib\site-packages\sklearn\compose\_column_transformer.py", line 681, in _fit_transform
    return Parallel(n_jobs=self.n_jobs)(
  File "f:\New folder\CampusPlacementPrediction\venv\lib\site-packages\sklearn\utils\parallel.py", line 65, in __call__
    return super().__call__(iterable_with_config)
  File "f:\New folder\CampusPlacementPrediction\venv\lib\site-packages\joblib\parallel.py", line 1863, in __call__
    return output if self.return_generator else list(output)
  File "f:\New folder\CampusPlacementPrediction\venv\lib\site-packages\joblib\parallel.py", line 1792, in _get_sequential_output
    res = func(*args, **kwargs)
  File "f:\New folder\CampusPlacementPrediction\venv\lib\site-packages\sklearn\utils\parallel.py", line 127, in __call__
    return self.function(*args, **kwargs)
  File "f:\New folder\CampusPlacementPrediction\venv\lib\site-packages\sklearn\pipeline.py", line 940, in _transform_one
    res = transformer.transform(X)
  File "f:\New folder\CampusPlacementPrediction\venv\lib\site-packages\sklearn\pipeline.py", line 696, in transform
    Xt = transform.transform(Xt)
  File "f:\New folder\CampusPlacementPrediction\venv\lib\site-packages\sklearn\utils\_set_output.py", line 157, in wrapped
    data_to_wrap = f(self, X, *args, **kwargs)
  File "f:\New folder\CampusPlacementPrediction\venv\lib\site-packages\sklearn\preprocessing\_encoders.py", line 1027, in transform
    X_int, X_mask = self._transform(
  File "f:\New folder\CampusPlacementPrediction\venv\lib\site-packages\sklearn\preprocessing\_encoders.py", line 200, in _transform
    raise ValueError(msg)
ValueError: Found unknown categories [None] in column 5 during transform

During handling of the above exception, another exception occurred:

Traceback (most recent call last):
  File "f:\New folder\CampusPlacementPrediction\venv\lib\site-packages\flask\app.py", line 1455, in wsgi_app
    response = self.full_dispatch_request()
  File "f:\New folder\CampusPlacementPrediction\venv\lib\site-packages\flask\app.py", line 869, in full_dispatch_request
    rv = self.handle_user_exception(e)
  File "f:\New folder\CampusPlacementPrediction\venv\lib\site-packages\flask\app.py", line 867, in full_dispatch_request
    rv = self.dispatch_request()
  File "f:\New folder\CampusPlacementPrediction\venv\lib\site-packages\flask\app.py", line 852, in dispatch_request
    return self.ensure_sync(self.view_functions[rule.endpoint])(**view_args)
  File "app.py", line 41, in submit
    result = prediction(inputs)
  File "F:\New folder\CampusPlacementPrediction\prediction.py", line 40, in prediction
    raise CustomException(e,sys)
src.exception.CustomException: Error occured in python script name [F:\New folder\CampusPlacementPrediction\prediction.py] line number [27] error message[Found unknown categories [None] in column 5 during transform]
[ 2023-10-16 17:33:58,966 ] 96 werkzeug - INFO - 127.0.0.1 - - [16/Oct/2023 17:33:58] "[35m[1mPOST /submit HTTP/1.1[0m" 500 -
